const errorHandling = [
  {
    question: "What is the purpose of the 'try...catch' statement in JavaScript?",
    options: ["To define a new function", "To handle asynchronous operations", "To declare variables", "To handle and control exceptions"],
    correctAnswer: "To handle and control exceptions",
  },
  {
    question: "Which keyword is used to throw a custom error in JavaScript?",
    options: ["raise", "error", "throw", "exception"],
    correctAnswer: "throw",
  },
  {
    question: "What is the 'finally' block used for in a 'try...catch' statement?",
    options: [
      "To define the try block",
      "To always execute code, regardless of whether an exception is thrown or caught",
      "To handle synchronous errors",
      "To catch exceptions that occur within the catch block",
    ],
    correctAnswer: "To always execute code, regardless of whether an exception is thrown or caught",
  },
  {
    question: "What is the purpose of the 'Error' object in JavaScript?",
    options: ["To create new variables", "To handle asynchronous operations", "To represent an error object", "To define custom functions"],
    correctAnswer: "To represent an error object",
  },
  {
    question: "Which method is used to log an error message to the console in JavaScript?",
    options: ["console.logError()", "console.error()", "console.logException()", "console.throwError()"],
    correctAnswer: "console.error()",
  },
];
module.exports = errorHandling;
